<?xml version="1.0"?>
<sdf version="1.4">
  <model>
    <static>false</static>

    <link name="base_link">

      <inertial>
        <mass>3</mass>
        <inertia>
          <ixx>0.006</ixx>
          <ixy>0.0</ixy>
          <ixz>0.0</ixz>
          <iyy>0.006</iyy>
          <iyz>0.0</iyz>
          <izz>0.006</izz>
        </inertia>
      </inertial>

      <collision name="base_link_collision">
        <pose>0 0 0.03 0 0 0</pose>
        <geometry>
          <box>
            <size>0.26 0.205 0.18</size>
          </box>
        </geometry>
      </collision>

      <visual name="base_link_visual">
        <pose>0 0 -0.06 0 0 0</pose>
        <geometry>
          <mesh>
            <uri>model://swarmie_description/meshes/Body.stl</uri>
          </mesh>
        </geometry>
        <material>
          <script>
            <name>Gazebo/Grey</name>
          </script>
        </material>
      </visual>

      <sensor type="ray" name="us_left_sensor">
        <pose>0.15 0.07 0.053 0 0 0.43633</pose>
        <visualize>false</visualize>
        <update_rate>5</update_rate>
        <ray>
          <scan>
            <horizontal>
              <samples>3</samples>
              <resolution>1.0</resolution>
              <min_angle>-.478</min_angle>
              <max_angle>0.478</max_angle>
            </horizontal>
          </scan>
          <range>
            <min>0.010</min>
            <max>3</max>
            <resolution>0.01</resolution>
          </range>
        </ray>
        <plugin name="us" filename="libhector_gazebo_ros_sonar.so">
          <gaussianNoise>0.005</gaussianNoise>
          <topicName>sonarLeft</topicName>
          <frameId>us_left_link</frameId>
        </plugin>
      </sensor>
      <sensor type="ray" name="us_right_sensor">
        <pose>0.15 -0.07 0.053 0 0 -0.43633</pose>
        <visualize>false</visualize>
        <update_rate>5</update_rate>
        <ray>
          <scan>
            <horizontal>
              <samples>3</samples>
              <resolution>1.0</resolution>
              <min_angle>-.478</min_angle>
              <max_angle>0.478</max_angle>
            </horizontal>
          </scan>
          <range>
            <min>0.010</min>
            <max>3</max>
            <resolution>0.01</resolution>
          </range>
        </ray>
        <plugin name="us" filename="libhector_gazebo_ros_sonar.so">
          <gaussianNoise>0.005</gaussianNoise>
          <topicName>sonarRight</topicName>
          <frameId>us_right_link</frameId>
        </plugin>
      </sensor>
      <sensor type="ray" name="us_center_sensor">
        <pose>0.15 0 0.053 0 0 0</pose>
        <visualize>false</visualize>
        <update_rate>5</update_rate>
        <ray>
          <scan>
            <horizontal>
              <samples>3</samples>
              <resolution>1.0</resolution>
              <min_angle>-.478</min_angle>
              <max_angle>0.478</max_angle>
            </horizontal>
          </scan>
          <range>
            <min>0.010</min>
            <max>3</max>
            <resolution>0.01</resolution>
          </range>
        </ray>
        <plugin name="us" filename="libhector_gazebo_ros_sonar.so">
          <gaussianNoise>0.005</gaussianNoise>
          <topicName>sonarCenter</topicName>
          <frameId>us_center_link</frameId>
        </plugin>
      </sensor>

      <!-- camera specification -->
      <sensor type="camera" name="camera">
        <pose>0.145 -0.0162 0.088 0.0 0.628 0.0</pose>
        <visualize>false</visualize>
        <update_rate>6.0</update_rate>
        <camera name="head">
          <horizontal_fov>1.0123</horizontal_fov>
          <image>
            <width>320</width>
            <height>240</height>
            <format>B8G8R8</format>
          </image>
          <clip>
            <near>0.02</near>
            <far>300</far>
          </clip>
          <noise>
            <type>gaussian</type>
            <mean>0.0</mean>
            <stddev>0.007</stddev>
          </noise>
        </camera>
        <plugin name="camera_controller" filename="libgazebo_ros_camera.so">
          <alwaysOn>true</alwaysOn>
          <updateRate>0.0</updateRate>
          <cameraName>camera</cameraName>
          <imageTopicName>camera/image</imageTopicName>
          <cameraInfoTopicName>camera/info</cameraInfoTopicName>
          <frameName>camera_link</frameName>
          <hackBaseline>0.1</hackBaseline>
          <distortionK1>0.0</distortionK1>
          <distortionK2>0.0</distortionK2>
          <distortionK3>0.0</distortionK3>
          <distortionT1>0.0</distortionT1>
          <distortionT2>0.0</distortionT2>
          <CxPrime>0.0</CxPrime>
          <Cx>0.0</Cx>
          <Cy>0.0</Cy>
          <focalLength>0.0</focalLength>
        </plugin>
      </sensor>

      <collision name="top_plate_colision">
        <pose>0 0 0.12 0 0 0</pose>
        <geometry>
          <box>
            <size>0.25 0.3 0.005</size>
          </box>
        </geometry>
      </collision>
      <visual name="top_plate_visual">
        <pose>0.0006 0 0.12 0 0 0</pose>
        <geometry>
          <mesh>
            <uri>model://swarmie_description/meshes/CoverPlate.stl</uri>
          </mesh>
        </geometry>
        <material>
          <script>
            <name>Gazebo/FlatBlack</name>
          </script>
        </material>
      </visual>
    </link> <!-- end body -->

    <link name="left_front_wheel">
      <pose>0.095 0.135 -0.03 0 0 0</pose>
      <inertial>
        <mass>1.0</mass>
        <inertia>
          <ixx>0.000776</ixx>
          <ixy>0.0</ixy>
          <ixz>0.0</ixz>
          <iyy>0.0012</iyy>
          <iyz>0.0</iyz>
          <izz>0.000776</izz>
        </inertia>
      </inertial>
      <collision name="collision">
        <pose>0 0 0 1.5708 0 0</pose>
        <geometry>
          <cylinder>
            <radius>.0575</radius>
            <length>.07</length>
          </cylinder>
        </geometry>
        <surface>
          <friction>
            <ode>
              <mu>0.8</mu>
              <mu2>0.7</mu2>
            </ode>
          </friction>
        </surface>
      </collision>
      <visual name="visual">
        <geometry>
          <mesh>
            <uri>model://swarmie_description/meshes/TireWheelLeft.stl</uri>
          </mesh>
        </geometry>
        <material>
          <script>
            <name>Gazebo/Grey</name>
          </script>
        </material>
      </visual>
    </link> <!-- end left_front_wheel -->

    <joint name="left_front" type="revolute">
      <parent>base_link</parent>
      <child>left_front_wheel</child>
      <axis>
        <xyz>0 1 0</xyz>
      </axis>
      <physics>
        <ode>
          <cfm>0.01</cfm>
          <erp>0.8</erp>
        </ode>
      </physics>
    </joint>

    <link name="right_front_wheel">
      <pose>0.095 -0.135 -0.03 0 0 0</pose>
      <inertial>
        <mass>1.0</mass>
        <inertia>
          <ixx>0.000776</ixx>
          <ixy>0.0</ixy>
          <ixz>0.0</ixz>
          <iyy>0.0012</iyy>
          <iyz>0.0</iyz>
          <izz>0.000776</izz>
        </inertia>
      </inertial>
      <collision name="collision">
        <pose>0 0 0 -1.5708 0 0</pose>
        <geometry>
          <cylinder>
            <radius>.0575</radius>
            <length>.07</length>
          </cylinder>
        </geometry>
        <surface>
          <friction>
            <ode>
              <mu>0.8</mu>
              <mu2>0.7</mu2>
            </ode>
          </friction>
        </surface>
      </collision>
      <visual name="visual">
        <geometry>
          <mesh>
            <uri>model://swarmie_description/meshes/TireWheelRight.stl</uri>
          </mesh>
        </geometry>
        <material>
          <script>
            <name>Gazebo/Grey</name>
          </script>
        </material>
      </visual>
    </link> <!-- end right_front_wheel -->

    <joint name="right_front" type="revolute">
      <parent>base_link</parent>
      <child>right_front_wheel</child>
      <axis>
        <xyz>0 1 0</xyz>
      </axis>
      <physics>
        <ode>
          <cfm>0.01</cfm>
          <erp>0.8</erp>
        </ode>
      </physics>
    </joint>

    <link name="left_rear_wheel">
      <pose>-0.095 0.135 -0.03 0 0 0</pose>
      <inertial>
        <mass>1.0</mass>
        <inertia>
          <ixx>0.000776</ixx>
          <ixy>0.0</ixy>
          <ixz>0.0</ixz>
          <iyy>0.0012</iyy>
          <iyz>0.0</iyz>
          <izz>0.000776</izz>
        </inertia>
      </inertial>
      <collision name="collision">
        <pose>0 0 0 1.5708 0 0</pose>
        <geometry>
          <cylinder>
            <radius>.0575</radius>
            <length>.07</length>
          </cylinder>
        </geometry>
        <surface>
          <friction>
            <ode>
              <mu>0.8</mu>
              <mu2>0.7</mu2>
            </ode>
          </friction>
        </surface>
      </collision>
      <visual name="visual">
        <geometry>
          <mesh>
            <uri>model://swarmie_description/meshes/TireWheelLeft.stl</uri>
          </mesh>
        </geometry>
        <material>
          <script>
            <name>Gazebo/Grey</name>
          </script>
        </material>
      </visual>
    </link> <!-- end left_rear_wheel -->

    <joint name="left_rear" type="revolute">
      <parent>base_link</parent>
      <child>left_rear_wheel</child>
      <axis>
        <xyz>0 1 0</xyz>
      </axis>
      <physics>
        <ode>
          <cfm>0.01</cfm>
          <erp>0.8</erp>
        </ode>
      </physics>
    </joint>

    <link name="right_rear_wheel">
      <pose>-0.095 -0.135 -0.03 0 0 0</pose>
      <inertial>
        <mass>1.0</mass>
        <inertia>
          <ixx>0.000776</ixx>
          <ixy>0.0</ixy>
          <ixz>0.0</ixz>
          <iyy>0.0012</iyy>
          <iyz>0.0</iyz>
          <izz>0.000776</izz>
        </inertia>
      </inertial>
      <collision name="collision">
        <pose>0 0 0 -1.5708 0 0</pose>
        <geometry>
          <cylinder>
            <radius>.0575</radius>
            <length>.07</length>
          </cylinder>
        </geometry>
        <surface>
          <friction>
            <ode>
              <mu>0.8</mu>
              <mu2>0.7</mu2>
            </ode>
          </friction>
        </surface>
      </collision>
      <visual name="visual">
        <geometry>
          <mesh>
            <uri>model://swarmie_description/meshes/TireWheelRight.stl</uri>
          </mesh>
        </geometry>
        <material>
          <script>
            <name>Gazebo/Grey</name>
          </script>
        </material>
      </visual>
    </link> <!-- end right_rear_wheel -->

    <joint name="right_rear" type="revolute">
      <parent>base_link</parent>
      <child>right_rear_wheel</child>
      <axis>
        <xyz>0 1 0</xyz>
      </axis>
      <physics>
        <ode>
          <cfm>0.01</cfm>
          <erp>0.8</erp>
        </ode>
      </physics>
    </joint>


    <!-- Skid Steer Drive plugin -->
    <plugin name="skid_steer_drive_controller" filename="libgazebo_ros_skid_steer_drive.so">
      <updateRate>10</updateRate>
      <leftFrontJoint>left_front</leftFrontJoint>
      <rightFrontJoint>right_front</rightFrontJoint>
      <leftRearJoint>left_rear</leftRearJoint>
      <rightRearJoint>right_rear</rightRearJoint>
      <wheelSeparation>0.27</wheelSeparation>
      <wheelDiameter>0.12</wheelDiameter>
      <robotBaseFrame>base_link</robotBaseFrame>
      <torque>2.8</torque>
      <commandTopic>skidsteer</commandTopic>
      <odometryTopic>odom</odometryTopic>
      <odometryFrame>odom</odometryFrame>
      <broadcastTF>0</broadcastTF>
    </plugin>

    <!-- GPS plugin -->
    <plugin name="gps_sim" filename="libhector_gazebo_ros_gps.so">
      <alwaysOn>1</alwaysOn>
      <updateRate>5</updateRate>
      <bodyName>base_link</bodyName>
      <frameId>base_link</frameId>
      <topicName>fix</topicName>
      <referenceLatitude>28.584810</referenceLatitude>
      <referenceLongitude>-80.649650</referenceLongitude>
      <referenceHeading>0.0</referenceHeading>
      <referenceAltitude>10.0</referenceAltitude>
      <offset>0.0 0.0 0.0</offset>
      <drift>0.1 0.1 0</drift>
      <driftFrequency>0.0 0.0 0.0</driftFrequency>
      <gaussianNoise>0.4 0.5 0.0</gaussianNoise>
    </plugin>

    <!-- IMU plugin -->
    <plugin name="imu_sim" filename="libhector_gazebo_ros_imu.so">
      <updateRate>10</updateRate>
      <bodyName>base_link</bodyName>
      <frameId>base_link</frameId>
      <topicName>imu</topicName>
      <xyzOffset>0 0 0</xyzOffset>
      <rpyOffset>0 0 0</rpyOffset>
      <gaussianNoise>0</gaussianNoise>
      <accelDrift>0.5 0.5 0.5</accelDrift>
      <accelGaussianNoise>0.35 0.35 0.3</accelGaussianNoise>
      <rateDrift>0.1 0.1 0.1</rateDrift>
      <rateGaussianNoise>0.05 0.05 0.015</rateGaussianNoise>
      <headingDrift>0.01</headingDrift>
      <headingGaussianNoise>0.01</headingGaussianNoise>
    </plugin>

  </model>
</sdf>
